Escrito en InfluxDB: 11.1°C
Últimos 30 valores de temperatura: [10.4, 10.4, 10.4, 10.4, 11.2, 11.3, 11.3, 11.3, 11.3, 11.3, 11.2, 11.0, 11.3, 11.3, 11.2, 11.2, 11.2, 11.1, 11.1, 11.1]
Escrito en InfluxDB: 11.2°C
Últimos valores de temperatura: [10.4, 10.4, 10.4, 10.4, 11.2, 11.3, 11.3, 11.3, 11.3, 11.3, 11.2, 11.0, 11.3, 11.3, 11.2, 11.2, 11.2, 11.2, 11.2, 11.1, 11.1, 11.1]
Escrito en InfluxDB: 11.2°C
Últimos valores de temperatura: [10.4, 10.4, 10.4, 10.4, 11.2, 11.3, 11.3, 11.3, 11.3, 11.3, 11.2, 11.0, 11.3, 11.3, 11.2, 11.2, 11.2, 11.2, 11.2, 11.2, 11.1, 11.1, 11.1]
Escrito en InfluxDB: 11.2°C
Últimos valores de temperatura: [10.4, 10.4, 10.4, 10.4, 11.2, 11.3, 11.3, 11.3, 11.3, 11.3, 11.2, 11.0, 11.3, 11.3, 11.2, 11.2, 11.2, 11.2, 11.2, 11.2, 11.2, 11.1, 11.1, 11.1]
Escrito en InfluxDB: 11.2°C
Últimos valores de temperatura: [10.4, 10.4, 10.4, 10.4, 11.2, 11.3, 11.3, 11.3, 11.3, 11.3, 11.2, 11.0, 11.3, 11.3, 11.2, 11.2, 11.2, 11.2, 11.2, 11.2, 11.2, 11.2, 11.1, 11.1, 11.1]
Escrito en InfluxDB: 11.1°C
Últimos valores de temperatura: [10.4, 10.4, 10.4, 10.4, 11.2, 11.3, 11.3, 11.3, 11.3, 11.3, 11.2, 11.0, 11.3, 11.3, 11.2, 11.2, 11.2, 11.1, 11.2, 11.2, 11.2, 11.2, 11.2, 11.1, 11.1, 11.1]
Traceback (most recent call last):
  File "/usr/local/lib/python3.9/site-packages/urllib3/connection.py", line 198, in _new_conn
    sock = connection.create_connection(
  File "/usr/local/lib/python3.9/site-packages/urllib3/util/connection.py", line 85, in create_connection
    raise err
  File "/usr/local/lib/python3.9/site-packages/urllib3/util/connection.py", line 73, in create_connection
    sock.connect(sa)
OSError: [Errno 101] Network is unreachable

The above exception was the direct cause of the following exception:

Traceback (most recent call last):
  File "/usr/local/lib/python3.9/site-packages/urllib3/connectionpool.py", line 787, in urlopen
    response = self._make_request(
  File "/usr/local/lib/python3.9/site-packages/urllib3/connectionpool.py", line 493, in _make_request
    conn.request(
  File "/usr/local/lib/python3.9/site-packages/urllib3/connection.py", line 445, in request
    self.endheaders()
  File "/usr/local/lib/python3.9/http/client.py", line 1280, in endheaders
    self._send_output(message_body, encode_chunked=encode_chunked)
  File "/usr/local/lib/python3.9/http/client.py", line 1040, in _send_output
    self.send(msg)
  File "/usr/local/lib/python3.9/http/client.py", line 980, in send
    self.connect()
  File "/usr/local/lib/python3.9/site-packages/urllib3/connection.py", line 276, in connect
    self.sock = self._new_conn()
  File "/usr/local/lib/python3.9/site-packages/urllib3/connection.py", line 213, in _new_conn
    raise NewConnectionError(
urllib3.exceptions.NewConnectionError: <urllib3.connection.HTTPConnection object at 0x754bb53ea400>: Failed to establish a new connection: [Errno 101] Network is unreachable

The above exception was the direct cause of the following exception:

Traceback (most recent call last):
  File "/usr/local/lib/python3.9/site-packages/requests/adapters.py", line 667, in send
    resp = conn.urlopen(
  File "/usr/local/lib/python3.9/site-packages/urllib3/connectionpool.py", line 841, in urlopen
    retries = retries.increment(
  File "/usr/local/lib/python3.9/site-packages/urllib3/util/retry.py", line 519, in increment
    raise MaxRetryError(_pool, url, reason) from reason  # type: ignore[arg-type]
urllib3.exceptions.MaxRetryError: HTTPConnectionPool(host='api.weatherapi.com', port=80): Max retries exceeded with url: /v1/current.json?key=d0a78c77a34b4d55879212336251302&q=Sant%20Quirze%20del%20Vall%C3%A9s&aqi=no (Caused by NewConnectionError('<urllib3.connection.HTTPConnection object at 0x754bb53ea400>: Failed to establish a new connection: [Errno 101] Network is unreachable'))

During handling of the above exception, another exception occurred:

Traceback (most recent call last):
  File "/app/weatherapi.py", line 37, in <module>
    temperature = get_weather()
  File "/app/weatherapi.py", line 26, in get_weather
    response = requests.get(url)
  File "/usr/local/lib/python3.9/site-packages/requests/api.py", line 73, in get
    return request("get", url, params=params, **kwargs)
  File "/usr/local/lib/python3.9/site-packages/requests/api.py", line 59, in request
    return session.request(method=method, url=url, **kwargs)
  File "/usr/local/lib/python3.9/site-packages/requests/sessions.py", line 589, in request
    resp = self.send(prep, **send_kwargs)
  File "/usr/local/lib/python3.9/site-packages/requests/sessions.py", line 703, in send
    r = adapter.send(request, **kwargs)
  File "/usr/local/lib/python3.9/site-packages/requests/adapters.py", line 700, in send
    raise ConnectionError(e, request=request)
requests.exceptions.ConnectionError: HTTPConnectionPool(host='api.weatherapi.com', port=80): Max retries exceeded with url: /v1/current.json?key=d0a78c77a34b4d55879212336251302&q=Sant%20Quirze%20del%20Vall%C3%A9s&aqi=no (Caused by NewConnectionError('<urllib3.connection.HTTPConnection object at 0x754bb53ea400>: Failed to establish a new connection: [Errno 101] Network is unreachable'))
Escrito en InfluxDB: 11.1°C
Últimos valores de temperatura: [10.4, 10.4, 10.4, 10.4, 11.2, 11.3, 11.3, 11.3, 11.3, 11.3, 11.2, 11.0, 11.3, 11.3, 11.2, 11.2, 11.2, 11.1, 11.1, 11.2, 11.2, 11.2, 11.2, 11.2, 11.1, 11.1, 11.1]
Escrito en InfluxDB: 11.0°C
Últimos valores de temperatura: [10.4, 10.4, 10.4, 10.4, 11.2, 11.3, 11.3, 11.3, 11.3, 11.3, 11.2, 11.0, 11.3, 11.3, 11.2, 11.2, 11.2, 11.0, 11.1, 11.1, 11.2, 11.2, 11.2, 11.2, 11.2, 11.1, 11.1, 11.1]
Escrito en InfluxDB: 11.4°C
Últimos valores de temperatura: [10.4, 10.4, 10.4, 10.4, 11.2, 11.3, 11.3, 11.3, 11.3, 11.3, 11.2, 11.0, 11.3, 11.3, 11.2, 11.2, 11.2, 11.4, 11.0, 11.1, 11.1, 11.2, 11.2, 11.2, 11.2, 11.2, 11.1, 11.1, 11.1]
Escrito en InfluxDB: 11.1°C
Últimos valores de temperatura: [10.4, 10.4, 10.4, 10.4, 11.2, 11.3, 11.3, 11.3, 11.3, 11.3, 11.2, 11.0, 11.3, 11.3, 11.2, 11.2, 11.2, 11.1, 11.4, 11.0, 11.1, 11.1, 11.2, 11.2, 11.2, 11.2, 11.2, 11.1, 11.1, 11.1]
Escrito en InfluxDB: 11.4°C
Últimos valores de temperatura: [10.4, 10.4, 10.4, 10.4, 11.2, 11.3, 11.3, 11.3, 11.3, 11.3, 11.2, 11.0, 11.3, 11.3, 11.2, 11.2, 11.2, 11.4, 11.1, 11.4, 11.0, 11.1, 11.1, 11.2, 11.2, 11.2, 11.2, 11.2, 11.1, 11.1, 11.1]
Escrito en InfluxDB: 11.1°C
Últimos valores de temperatura: [10.4, 10.4, 10.4, 10.4, 11.2, 11.3, 11.3, 11.3, 11.3, 11.3, 11.2, 11.0, 11.3, 11.3, 11.2, 11.2, 11.2, 11.1, 11.4, 11.1, 11.4, 11.0, 11.1, 11.1, 11.2, 11.2, 11.2, 11.2, 11.2, 11.1, 11.1, 11.1]
Escrito en InfluxDB: 11.2°C
Últimos valores de temperatura: [10.4, 10.4, 10.4, 10.4, 11.2, 11.3, 11.3, 11.3, 11.3, 11.3, 11.2, 11.0, 11.3, 11.3, 11.2, 11.2, 11.2, 11.2, 11.1, 11.4, 11.1, 11.4, 11.0, 11.1, 11.1, 11.2, 11.2, 11.2, 11.2, 11.2, 11.1, 11.1, 11.1]
Traceback (most recent call last):
  File "/usr/local/lib/python3.9/site-packages/urllib3/connection.py", line 198, in _new_conn
    sock = connection.create_connection(
  File "/usr/local/lib/python3.9/site-packages/urllib3/util/connection.py", line 85, in create_connection
    raise err
  File "/usr/local/lib/python3.9/site-packages/urllib3/util/connection.py", line 73, in create_connection
    sock.connect(sa)
OSError: [Errno 101] Network is unreachable

The above exception was the direct cause of the following exception:

Traceback (most recent call last):
  File "/usr/local/lib/python3.9/site-packages/urllib3/connectionpool.py", line 787, in urlopen
    response = self._make_request(
  File "/usr/local/lib/python3.9/site-packages/urllib3/connectionpool.py", line 493, in _make_request
    conn.request(
  File "/usr/local/lib/python3.9/site-packages/urllib3/connection.py", line 445, in request
    self.endheaders()
  File "/usr/local/lib/python3.9/http/client.py", line 1280, in endheaders
    self._send_output(message_body, encode_chunked=encode_chunked)
  File "/usr/local/lib/python3.9/http/client.py", line 1040, in _send_output
    self.send(msg)
  File "/usr/local/lib/python3.9/http/client.py", line 980, in send
    self.connect()
  File "/usr/local/lib/python3.9/site-packages/urllib3/connection.py", line 276, in connect
    self.sock = self._new_conn()
  File "/usr/local/lib/python3.9/site-packages/urllib3/connection.py", line 213, in _new_conn
    raise NewConnectionError(
urllib3.exceptions.NewConnectionError: <urllib3.connection.HTTPConnection object at 0x744e6e66a400>: Failed to establish a new connection: [Errno 101] Network is unreachable

The above exception was the direct cause of the following exception:

Traceback (most recent call last):
  File "/usr/local/lib/python3.9/site-packages/requests/adapters.py", line 667, in send
    resp = conn.urlopen(
  File "/usr/local/lib/python3.9/site-packages/urllib3/connectionpool.py", line 841, in urlopen
    retries = retries.increment(
  File "/usr/local/lib/python3.9/site-packages/urllib3/util/retry.py", line 519, in increment
    raise MaxRetryError(_pool, url, reason) from reason  # type: ignore[arg-type]
urllib3.exceptions.MaxRetryError: HTTPConnectionPool(host='api.weatherapi.com', port=80): Max retries exceeded with url: /v1/current.json?key=d0a78c77a34b4d55879212336251302&q=Sant%20Quirze%20del%20Vall%C3%A9s&aqi=no (Caused by NewConnectionError('<urllib3.connection.HTTPConnection object at 0x744e6e66a400>: Failed to establish a new connection: [Errno 101] Network is unreachable'))

During handling of the above exception, another exception occurred:

Traceback (most recent call last):
  File "/app/weatherapi.py", line 37, in <module>
    temperature = get_weather()
  File "/app/weatherapi.py", line 26, in get_weather
    response = requests.get(url)
  File "/usr/local/lib/python3.9/site-packages/requests/api.py", line 73, in get
    return request("get", url, params=params, **kwargs)
  File "/usr/local/lib/python3.9/site-packages/requests/api.py", line 59, in request
    return session.request(method=method, url=url, **kwargs)
  File "/usr/local/lib/python3.9/site-packages/requests/sessions.py", line 589, in request
    resp = self.send(prep, **send_kwargs)
  File "/usr/local/lib/python3.9/site-packages/requests/sessions.py", line 703, in send
    r = adapter.send(request, **kwargs)
  File "/usr/local/lib/python3.9/site-packages/requests/adapters.py", line 700, in send
    raise ConnectionError(e, request=request)
requests.exceptions.ConnectionError: HTTPConnectionPool(host='api.weatherapi.com', port=80): Max retries exceeded with url: /v1/current.json?key=d0a78c77a34b4d55879212336251302&q=Sant%20Quirze%20del%20Vall%C3%A9s&aqi=no (Caused by NewConnectionError('<urllib3.connection.HTTPConnection object at 0x744e6e66a400>: Failed to establish a new connection: [Errno 101] Network is unreachable'))
Escrito en InfluxDB: 11.2°C
Últimos valores de temperatura: [10.4, 10.4, 10.4, 10.4, 11.2, 11.3, 11.3, 11.3, 11.3, 11.3, 11.2, 11.0, 11.3, 11.3, 11.2, 11.2, 11.2, 11.2, 11.2, 11.2, 11.1, 11.4, 11.1, 11.4, 11.0, 11.1, 11.1, 11.2, 11.2, 11.2, 11.2, 11.2, 11.1, 11.1, 11.1]
Escrito en InfluxDB: 11.1°C
Últimos valores de temperatura: [10.4, 10.4, 10.4, 10.4, 11.2, 11.3, 11.3, 11.3, 11.3, 11.3, 11.2, 11.0, 11.3, 11.3, 11.2, 11.2, 11.2, 11.1, 11.2, 11.2, 11.2, 11.1, 11.4, 11.1, 11.4, 11.0, 11.1, 11.1, 11.2, 11.2, 11.2, 11.2, 11.2, 11.1, 11.1, 11.1]
Escrito en InfluxDB: 11.1°C
Últimos valores de temperatura: [10.4, 10.4, 10.4, 10.4, 11.2, 11.3, 11.3, 11.3, 11.3, 11.3, 11.2, 11.0, 11.3, 11.3, 11.2, 11.2, 11.2, 11.1, 11.1, 11.2, 11.2, 11.2, 11.1, 11.4, 11.1, 11.4, 11.0, 11.1, 11.1, 11.2, 11.2, 11.2, 11.2, 11.2, 11.1, 11.1, 11.1]
Escrito en InfluxDB: 11.1°C
Últimos valores de temperatura: [10.4, 10.4, 10.4, 10.4, 11.2, 11.3, 11.3, 11.3, 11.3, 11.3, 11.2, 11.0, 11.3, 11.3, 11.2, 11.2, 11.2, 11.1, 11.1, 11.1, 11.2, 11.2, 11.2, 11.1, 11.4, 11.1, 11.4, 11.0, 11.1, 11.1, 11.2, 11.2, 11.2, 11.2, 11.2, 11.1, 11.1, 11.1]
Escrito en InfluxDB: 11.2°C
Últimos valores de temperatura: [10.4, 10.4, 10.4, 10.4, 11.2, 11.3, 11.3, 11.3, 11.3, 11.3, 11.2, 11.0, 11.3, 11.3, 11.2, 11.2, 11.2, 11.2, 11.1, 11.1, 11.1, 11.2, 11.2, 11.2, 11.1, 11.4, 11.1, 11.4, 11.0, 11.1, 11.1, 11.2, 11.2, 11.2, 11.2, 11.2, 11.1, 11.1, 11.1]
Escrito en InfluxDB: 11.4°C
Últimos valores de temperatura: [10.4, 10.4, 10.4, 10.4, 11.2, 11.3, 11.3, 11.3, 11.3, 11.3, 11.2, 11.0, 11.3, 11.3, 11.2, 11.2, 11.2, 11.4, 11.2, 11.1, 11.1, 11.1, 11.2, 11.2, 11.2, 11.1, 11.4, 11.1, 11.4, 11.0, 11.1, 11.1, 11.2, 11.2, 11.2, 11.2, 11.2, 11.1, 11.1, 11.1]
Escrito en InfluxDB: 11.1°C
Últimos valores de temperatura: [10.4, 10.4, 10.4, 10.4, 11.2, 11.3, 11.3, 11.3, 11.3, 11.3, 11.2, 11.0, 11.3, 11.3, 11.2, 11.2, 11.2, 11.1, 11.4, 11.2, 11.1, 11.1, 11.1, 11.2, 11.2, 11.2, 11.1, 11.4, 11.1, 11.4, 11.0, 11.1, 11.1, 11.2, 11.2, 11.2, 11.2, 11.2, 11.1, 11.1, 11.1]
Escrito en InfluxDB: 11.2°C
Últimos valores de temperatura: [10.4, 10.4, 10.4, 10.4, 11.2, 11.3, 11.3, 11.3, 11.3, 11.3, 11.2, 11.0, 11.3, 11.3, 11.2, 11.2, 11.2, 11.2, 11.1, 11.4, 11.2, 11.1, 11.1, 11.1, 11.2, 11.2, 11.2, 11.1, 11.4, 11.1, 11.4, 11.0, 11.1, 11.1, 11.2, 11.2, 11.2, 11.2, 11.2, 11.1, 11.1, 11.1]
Traceback (most recent call last):
  File "/usr/local/lib/python3.9/site-packages/urllib3/connection.py", line 198, in _new_conn
    sock = connection.create_connection(
  File "/usr/local/lib/python3.9/site-packages/urllib3/util/connection.py", line 85, in create_connection
    raise err
  File "/usr/local/lib/python3.9/site-packages/urllib3/util/connection.py", line 73, in create_connection
    sock.connect(sa)
OSError: [Errno 101] Network is unreachable

The above exception was the direct cause of the following exception:

Traceback (most recent call last):
  File "/usr/local/lib/python3.9/site-packages/urllib3/connectionpool.py", line 787, in urlopen
    response = self._make_request(
  File "/usr/local/lib/python3.9/site-packages/urllib3/connectionpool.py", line 493, in _make_request
    conn.request(
  File "/usr/local/lib/python3.9/site-packages/urllib3/connection.py", line 445, in request
    self.endheaders()
  File "/usr/local/lib/python3.9/http/client.py", line 1280, in endheaders
    self._send_output(message_body, encode_chunked=encode_chunked)
  File "/usr/local/lib/python3.9/http/client.py", line 1040, in _send_output
    self.send(msg)
  File "/usr/local/lib/python3.9/http/client.py", line 980, in send
    self.connect()
  File "/usr/local/lib/python3.9/site-packages/urllib3/connection.py", line 276, in connect
    self.sock = self._new_conn()
  File "/usr/local/lib/python3.9/site-packages/urllib3/connection.py", line 213, in _new_conn
    raise NewConnectionError(
urllib3.exceptions.NewConnectionError: <urllib3.connection.HTTPConnection object at 0x72485186a400>: Failed to establish a new connection: [Errno 101] Network is unreachable

The above exception was the direct cause of the following exception:

Traceback (most recent call last):
  File "/usr/local/lib/python3.9/site-packages/requests/adapters.py", line 667, in send
    resp = conn.urlopen(
  File "/usr/local/lib/python3.9/site-packages/urllib3/connectionpool.py", line 841, in urlopen
    retries = retries.increment(
  File "/usr/local/lib/python3.9/site-packages/urllib3/util/retry.py", line 519, in increment
    raise MaxRetryError(_pool, url, reason) from reason  # type: ignore[arg-type]
urllib3.exceptions.MaxRetryError: HTTPConnectionPool(host='api.weatherapi.com', port=80): Max retries exceeded with url: /v1/current.json?key=d0a78c77a34b4d55879212336251302&q=Sant%20Quirze%20del%20Vall%C3%A9s&aqi=no (Caused by NewConnectionError('<urllib3.connection.HTTPConnection object at 0x72485186a400>: Failed to establish a new connection: [Errno 101] Network is unreachable'))

During handling of the above exception, another exception occurred:

Traceback (most recent call last):
  File "/app/weatherapi.py", line 37, in <module>
    temperature = get_weather()
  File "/app/weatherapi.py", line 26, in get_weather
    response = requests.get(url)
  File "/usr/local/lib/python3.9/site-packages/requests/api.py", line 73, in get
    return request("get", url, params=params, **kwargs)
  File "/usr/local/lib/python3.9/site-packages/requests/api.py", line 59, in request
    return session.request(method=method, url=url, **kwargs)
  File "/usr/local/lib/python3.9/site-packages/requests/sessions.py", line 589, in request
    resp = self.send(prep, **send_kwargs)
  File "/usr/local/lib/python3.9/site-packages/requests/sessions.py", line 703, in send
    r = adapter.send(request, **kwargs)
  File "/usr/local/lib/python3.9/site-packages/requests/adapters.py", line 700, in send
    raise ConnectionError(e, request=request)
requests.exceptions.ConnectionError: HTTPConnectionPool(host='api.weatherapi.com', port=80): Max retries exceeded with url: /v1/current.json?key=d0a78c77a34b4d55879212336251302&q=Sant%20Quirze%20del%20Vall%C3%A9s&aqi=no (Caused by NewConnectionError('<urllib3.connection.HTTPConnection object at 0x72485186a400>: Failed to establish a new connection: [Errno 101] Network is unreachable'))
Escrito en InfluxDB: 11.3°C
Últimos valores de temperatura: [10.4, 10.4, 10.4, 10.4, 11.2, 11.3, 11.3, 11.3, 11.3, 11.3, 11.2, 11.0, 11.3, 11.3, 11.2, 11.2, 11.2, 11.3, 11.2, 11.1, 11.4, 11.2, 11.1, 11.1, 11.1, 11.2, 11.2, 11.2, 11.1, 11.4, 11.1, 11.4, 11.0, 11.1, 11.1, 11.2, 11.2, 11.2, 11.2, 11.2, 11.1, 11.1, 11.1]
Escrito en InfluxDB: 11.3°C
Últimos valores de temperatura: [10.4, 10.4, 10.4, 10.4, 11.2, 11.3, 11.3, 11.3, 11.3, 11.3, 11.2, 11.0, 11.3, 11.3, 11.2, 11.2, 11.2, 11.3, 11.3, 11.2, 11.1, 11.4, 11.2, 11.1, 11.1, 11.1, 11.2, 11.2, 11.2, 11.1, 11.4, 11.1, 11.4, 11.0, 11.1, 11.1, 11.2, 11.2, 11.2, 11.2, 11.2, 11.1, 11.1, 11.1]
Escrito en InfluxDB: 11.3°C
Últimos valores de temperatura: [10.4, 10.4, 10.4, 10.4, 11.2, 11.3, 11.3, 11.3, 11.3, 11.3, 11.2, 11.0, 11.3, 11.3, 11.2, 11.2, 11.2, 11.3, 11.3, 11.3, 11.2, 11.1, 11.4, 11.2, 11.1, 11.1, 11.1, 11.2, 11.2, 11.2, 11.1, 11.4, 11.1, 11.4, 11.0, 11.1, 11.1, 11.2, 11.2, 11.2, 11.2, 11.2, 11.1, 11.1, 11.1]
Escrito en InfluxDB: 11.3°C
Últimos valores de temperatura: [10.4, 10.4, 10.4, 10.4, 11.2, 11.3, 11.3, 11.3, 11.3, 11.3, 11.2, 11.0, 11.3, 11.3, 11.2, 11.2, 11.2, 11.3, 11.3, 11.3, 11.3, 11.2, 11.1, 11.4, 11.2, 11.1, 11.1, 11.1, 11.2, 11.2, 11.2, 11.1, 11.4, 11.1, 11.4, 11.0, 11.1, 11.1, 11.2, 11.2, 11.2, 11.2, 11.2, 11.1, 11.1, 11.1]
Escrito en InfluxDB: 10.7°C
Últimos valores de temperatura: [10.4, 10.4, 10.4, 10.4, 11.2, 11.3, 11.3, 11.3, 11.3, 11.3, 11.2, 11.0, 11.3, 11.3, 11.2, 11.2, 11.2, 10.7, 11.3, 11.3, 11.3, 11.3, 11.2, 11.1, 11.4, 11.2, 11.1, 11.1, 11.1, 11.2, 11.2, 11.2, 11.1, 11.4, 11.1, 11.4, 11.0, 11.1, 11.1, 11.2, 11.2, 11.2, 11.2, 11.2, 11.1, 11.1, 11.1]
Escrito en InfluxDB: 10.6°C
Últimos valores de temperatura: [10.4, 10.4, 10.4, 10.4, 11.2, 11.3, 11.3, 11.3, 11.3, 11.3, 11.2, 11.0, 11.3, 11.3, 11.2, 11.2, 11.2, 10.6, 10.7, 11.3, 11.3, 11.3, 11.3, 11.2, 11.1, 11.4, 11.2, 11.1, 11.1, 11.1, 11.2, 11.2, 11.2, 11.1, 11.4, 11.1, 11.4, 11.0, 11.1, 11.1, 11.2, 11.2, 11.2, 11.2, 11.2, 11.1, 11.1]
Escrito en InfluxDB: 10.2°C
Últimos valores de temperatura: [10.4, 10.4, 10.4, 10.4, 11.2, 11.3, 11.3, 11.3, 11.3, 11.3, 11.2, 11.0, 11.3, 11.3, 11.2, 11.2, 11.2, 10.2, 10.6, 10.7, 11.3, 11.3, 11.3, 11.3, 11.2, 11.1, 11.4, 11.2, 11.1, 11.1, 11.1, 11.2, 11.2, 11.2, 11.1, 11.4, 11.1, 11.4, 11.0, 11.1, 11.1, 11.2, 11.2, 11.2, 11.2, 11.2, 11.1]
Escrito en InfluxDB: 10.0°C
Últimos valores de temperatura: [10.4, 10.4, 10.4, 10.4, 11.2, 11.3, 11.3, 11.3, 11.3, 11.3, 11.2, 11.0, 11.3, 11.3, 11.2, 11.2, 11.2, 10.0, 10.2, 10.6, 10.7, 11.3, 11.3, 11.3, 11.3, 11.2, 11.1, 11.4, 11.2, 11.1, 11.1, 11.1, 11.2, 11.2, 11.2, 11.1, 11.4, 11.1, 11.4, 11.0, 11.1, 11.1, 11.2, 11.2, 11.2, 11.2, 11.2]
Escrito en InfluxDB: 10.4°C
Últimos valores de temperatura: [10.4, 10.4, 10.4, 10.4, 11.2, 11.3, 11.3, 11.3, 11.3, 11.3, 11.2, 11.0, 11.3, 11.3, 11.2, 11.2, 11.2, 10.4, 10.0, 10.2, 10.6, 10.7, 11.3, 11.3, 11.3, 11.3, 11.2, 11.1, 11.4, 11.2, 11.1, 11.1, 11.1, 11.2, 11.2, 11.2, 11.1, 11.4, 11.1, 11.4, 11.0, 11.1, 11.1, 11.2, 11.2, 11.2, 11.2]
Escrito en InfluxDB: 10.3°C
Últimos valores de temperatura: [10.4, 10.4, 10.4, 10.4, 11.2, 11.3, 11.3, 11.3, 11.3, 11.3, 11.2, 11.0, 11.3, 11.3, 11.2, 11.2, 11.2, 10.3, 10.4, 10.0, 10.2, 10.6, 10.7, 11.3, 11.3, 11.3, 11.3, 11.2, 11.1, 11.4, 11.2, 11.1, 11.1, 11.1, 11.2, 11.2, 11.2, 11.1, 11.4, 11.1, 11.4, 11.0, 11.1, 11.1, 11.2, 11.2, 11.2]
Escrito en InfluxDB: 10.1°C
Últimos valores de temperatura: [10.4, 10.4, 10.4, 10.4, 11.2, 11.3, 11.3, 11.3, 11.3, 11.3, 11.2, 11.0, 11.3, 11.3, 11.2, 11.2, 11.2, 10.1, 10.3, 10.4, 10.0, 10.2, 10.6, 10.7, 11.3, 11.3, 11.3, 11.3, 11.2, 11.1, 11.4, 11.2, 11.1, 11.1, 11.1, 11.2, 11.2, 11.2, 11.1, 11.4, 11.1, 11.4, 11.0, 11.1, 11.1, 11.2, 11.2]
Escrito en InfluxDB: 10.1°C
Últimos valores de temperatura: [10.4, 10.4, 10.4, 10.4, 11.2, 11.3, 11.3, 11.3, 11.3, 11.3, 11.2, 11.0, 11.3, 11.3, 11.2, 11.2, 11.2, 10.1, 10.1, 10.3, 10.4, 10.0, 10.2, 10.6, 10.7, 11.3, 11.3, 11.3, 11.3, 11.2, 11.1, 11.4, 11.2, 11.1, 11.1, 11.1, 11.2, 11.2, 11.2, 11.1, 11.4, 11.1, 11.4, 11.0, 11.1, 11.1, 11.2]
Escrito en InfluxDB: 10.2°C
Últimos valores de temperatura: [10.4, 10.4, 10.4, 10.4, 11.2, 11.3, 11.3, 11.3, 11.3, 11.3, 11.2, 11.0, 11.3, 11.3, 11.2, 11.2, 11.2, 10.2, 10.1, 10.1, 10.3, 10.4, 10.0, 10.2, 10.6, 10.7, 11.3, 11.3, 11.3, 11.3, 11.2, 11.1, 11.4, 11.2, 11.1, 11.1, 11.1, 11.2, 11.2, 11.2, 11.1, 11.4, 11.1, 11.4, 11.0, 11.1, 11.1]
Escrito en InfluxDB: 10.2°C
Últimos valores de temperatura: [10.4, 10.4, 10.4, 10.4, 11.2, 11.3, 11.3, 11.3, 11.3, 11.3, 11.2, 11.0, 11.3, 11.3, 11.2, 11.2, 11.2, 10.2, 10.2, 10.1, 10.1, 10.3, 10.4, 10.0, 10.2, 10.6, 10.7, 11.3, 11.3, 11.3, 11.3, 11.2, 11.1, 11.4, 11.2, 11.1, 11.1, 11.1, 11.2, 11.2, 11.2, 11.1, 11.4, 11.1, 11.4, 11.0, 11.1]
Traceback (most recent call last):
  File "/usr/local/lib/python3.9/site-packages/urllib3/connection.py", line 198, in _new_conn
    sock = connection.create_connection(
  File "/usr/local/lib/python3.9/site-packages/urllib3/util/connection.py", line 85, in create_connection
    raise err
  File "/usr/local/lib/python3.9/site-packages/urllib3/util/connection.py", line 73, in create_connection
    sock.connect(sa)
OSError: [Errno 101] Network is unreachable

The above exception was the direct cause of the following exception:

Traceback (most recent call last):
  File "/usr/local/lib/python3.9/site-packages/urllib3/connectionpool.py", line 787, in urlopen
    response = self._make_request(
  File "/usr/local/lib/python3.9/site-packages/urllib3/connectionpool.py", line 493, in _make_request
    conn.request(
  File "/usr/local/lib/python3.9/site-packages/urllib3/connection.py", line 445, in request
    self.endheaders()
  File "/usr/local/lib/python3.9/http/client.py", line 1280, in endheaders
    self._send_output(message_body, encode_chunked=encode_chunked)
  File "/usr/local/lib/python3.9/http/client.py", line 1040, in _send_output
    self.send(msg)
  File "/usr/local/lib/python3.9/http/client.py", line 980, in send
    self.connect()
  File "/usr/local/lib/python3.9/site-packages/urllib3/connection.py", line 276, in connect
    self.sock = self._new_conn()
  File "/usr/local/lib/python3.9/site-packages/urllib3/connection.py", line 213, in _new_conn
    raise NewConnectionError(
urllib3.exceptions.NewConnectionError: <urllib3.connection.HTTPConnection object at 0x7458c5a69400>: Failed to establish a new connection: [Errno 101] Network is unreachable

The above exception was the direct cause of the following exception:

Traceback (most recent call last):
  File "/usr/local/lib/python3.9/site-packages/requests/adapters.py", line 667, in send
    resp = conn.urlopen(
  File "/usr/local/lib/python3.9/site-packages/urllib3/connectionpool.py", line 841, in urlopen
    retries = retries.increment(
  File "/usr/local/lib/python3.9/site-packages/urllib3/util/retry.py", line 519, in increment
    raise MaxRetryError(_pool, url, reason) from reason  # type: ignore[arg-type]
urllib3.exceptions.MaxRetryError: HTTPConnectionPool(host='api.weatherapi.com', port=80): Max retries exceeded with url: /v1/current.json?key=d0a78c77a34b4d55879212336251302&q=Sant%20Quirze%20del%20Vall%C3%A9s&aqi=no (Caused by NewConnectionError('<urllib3.connection.HTTPConnection object at 0x7458c5a69400>: Failed to establish a new connection: [Errno 101] Network is unreachable'))

During handling of the above exception, another exception occurred:

Traceback (most recent call last):
  File "/app/weatherapi.py", line 37, in <module>
    temperature = get_weather()
  File "/app/weatherapi.py", line 26, in get_weather
    response = requests.get(url)
  File "/usr/local/lib/python3.9/site-packages/requests/api.py", line 73, in get
    return request("get", url, params=params, **kwargs)
  File "/usr/local/lib/python3.9/site-packages/requests/api.py", line 59, in request
    return session.request(method=method, url=url, **kwargs)
  File "/usr/local/lib/python3.9/site-packages/requests/sessions.py", line 589, in request
    resp = self.send(prep, **send_kwargs)
  File "/usr/local/lib/python3.9/site-packages/requests/sessions.py", line 703, in send
    r = adapter.send(request, **kwargs)
  File "/usr/local/lib/python3.9/site-packages/requests/adapters.py", line 700, in send
    raise ConnectionError(e, request=request)
requests.exceptions.ConnectionError: HTTPConnectionPool(host='api.weatherapi.com', port=80): Max retries exceeded with url: /v1/current.json?key=d0a78c77a34b4d55879212336251302&q=Sant%20Quirze%20del%20Vall%C3%A9s&aqi=no (Caused by NewConnectionError('<urllib3.connection.HTTPConnection object at 0x7458c5a69400>: Failed to establish a new connection: [Errno 101] Network is unreachable'))
Escrito en InfluxDB: 10.2°C
Últimos valores de temperatura: [10.4, 10.4, 10.4, 10.4, 11.2, 11.3, 11.3, 11.3, 11.3, 11.3, 11.2, 11.0, 11.3, 11.3, 11.2, 11.2, 11.2, 10.2, 10.2, 10.2, 10.1, 10.1, 10.3, 10.4, 10.0, 10.2, 10.6, 10.7, 11.3, 11.3, 11.3, 11.3, 11.2, 11.1, 11.4, 11.2, 11.1, 11.1, 11.1, 11.2, 11.2, 11.2, 11.1, 11.4, 11.1, 11.4, 11.0]
Escrito en InfluxDB: 10.1°C
Últimos valores de temperatura: [10.4, 10.4, 10.4, 10.4, 11.2, 11.3, 11.3, 11.3, 11.3, 11.3, 11.2, 11.0, 11.3, 11.3, 11.2, 11.2, 11.2, 10.1, 10.2, 10.2, 10.2, 10.1, 10.1, 10.3, 10.4, 10.0, 10.2, 10.6, 10.7, 11.3, 11.3, 11.3, 11.3, 11.2, 11.1, 11.4, 11.2, 11.1, 11.1, 11.1, 11.2, 11.2, 11.2, 11.1, 11.4, 11.1, 11.4]
Escrito en InfluxDB: 10.4°C
Últimos valores de temperatura: [10.4, 10.4, 10.4, 10.4, 11.2, 11.3, 11.3, 11.3, 11.3, 11.3, 11.2, 11.0, 11.3, 11.3, 11.2, 11.2, 11.2, 10.4, 10.1, 10.2, 10.2, 10.2, 10.1, 10.1, 10.3, 10.4, 10.0, 10.2, 10.6, 10.7, 11.3, 11.3, 11.3, 11.3, 11.2, 11.1, 11.4, 11.2, 11.1, 11.1, 11.1, 11.2, 11.2, 11.2, 11.1, 11.4, 11.1]
Escrito en InfluxDB: 10.2°C
Últimos valores de temperatura: [10.4, 10.4, 10.4, 10.4, 11.2, 11.3, 11.3, 11.3, 11.3, 11.3, 11.2, 11.0, 11.3, 11.3, 11.2, 11.2, 11.2, 10.2, 10.4, 10.1, 10.2, 10.2, 10.2, 10.1, 10.1, 10.3, 10.4, 10.0, 10.2, 10.6, 10.7, 11.3, 11.3, 11.3, 11.3, 11.2, 11.1, 11.4, 11.2, 11.1, 11.1, 11.1, 11.2, 11.2, 11.2, 11.1, 11.4]
Escrito en InfluxDB: 10.1°C
Últimos valores de temperatura: [10.4, 10.4, 10.4, 10.4, 11.2, 11.3, 11.3, 11.3, 11.3, 11.3, 11.2, 11.0, 11.3, 11.3, 11.2, 11.2, 11.2, 10.1, 10.2, 10.4, 10.1, 10.2, 10.2, 10.2, 10.1, 10.1, 10.3, 10.4, 10.0, 10.2, 10.6, 10.7, 11.3, 11.3, 11.3, 11.3, 11.2, 11.1, 11.4, 11.2, 11.1, 11.1, 11.1, 11.2, 11.2, 11.2, 11.1]
Escrito en InfluxDB: 10.3°C
Últimos valores de temperatura: [10.4, 10.4, 10.4, 10.4, 11.2, 11.3, 11.3, 11.3, 11.3, 11.3, 11.2, 11.0, 11.3, 11.3, 11.2, 11.2, 11.2, 10.3, 10.1, 10.2, 10.4, 10.1, 10.2, 10.2, 10.2, 10.1, 10.1, 10.3, 10.4, 10.0, 10.2, 10.6, 10.7, 11.3, 11.3, 11.3, 11.3, 11.2, 11.1, 11.4, 11.2, 11.1, 11.1, 11.1, 11.2, 11.2, 11.2]
Escrito en InfluxDB: 10.1°C
Últimos valores de temperatura: [10.4, 10.4, 10.4, 10.4, 11.2, 11.3, 11.3, 11.3, 11.3, 11.3, 11.2, 11.0, 11.3, 11.3, 11.2, 11.2, 11.2, 10.1, 10.3, 10.1, 10.2, 10.4, 10.1, 10.2, 10.2, 10.2, 10.1, 10.1, 10.3, 10.4, 10.0, 10.2, 10.6, 10.7, 11.3, 11.3, 11.3, 11.3, 11.2, 11.1, 11.4, 11.2, 11.1, 11.1, 11.1, 11.2, 11.2]
Escrito en InfluxDB: 9.2°C
Últimos valores de temperatura: [10.4, 10.4, 10.4, 10.4, 11.2, 11.3, 11.3, 11.3, 11.3, 11.3, 11.2, 11.0, 11.3, 11.3, 11.2, 11.2, 11.2, 9.2, 10.1, 10.3, 10.1, 10.2, 10.4, 10.1, 10.2, 10.2, 10.2, 10.1, 10.1, 10.3, 10.4, 10.0, 10.2, 10.6, 10.7, 11.3, 11.3, 11.3, 11.3, 11.2, 11.1, 11.4, 11.2, 11.1, 11.1, 11.1, 11.2]
Escrito en InfluxDB: 9.3°C
Últimos valores de temperatura: [10.4, 10.4, 10.4, 10.4, 11.2, 11.3, 11.3, 11.3, 11.3, 11.3, 11.2, 11.0, 11.3, 11.3, 11.2, 11.2, 11.2, 9.3, 9.2, 10.1, 10.3, 10.1, 10.2, 10.4, 10.1, 10.2, 10.2, 10.2, 10.1, 10.1, 10.3, 10.4, 10.0, 10.2, 10.6, 10.7, 11.3, 11.3, 11.3, 11.3, 11.2, 11.1, 11.4, 11.2, 11.1, 11.1, 11.1]
Escrito en InfluxDB: 9.3°C
Últimos valores de temperatura: [10.4, 10.4, 10.4, 10.4, 11.2, 11.3, 11.3, 11.3, 11.3, 11.3, 11.2, 11.0, 11.3, 11.3, 11.2, 11.2, 11.2, 9.3, 9.3, 9.2, 10.1, 10.3, 10.1, 10.2, 10.4, 10.1, 10.2, 10.2, 10.2, 10.1, 10.1, 10.3, 10.4, 10.0, 10.2, 10.6, 10.7, 11.3, 11.3, 11.3, 11.3, 11.2, 11.1, 11.4, 11.2, 11.1, 11.1]
Escrito en InfluxDB: 9.4°C
Últimos valores de temperatura: [10.4, 10.4, 10.4, 10.4, 11.2, 11.3, 11.3, 11.3, 11.3, 11.3, 11.2, 11.0, 11.3, 11.3, 11.2, 11.2, 11.2, 9.4, 9.3, 9.3, 9.2, 10.1, 10.3, 10.1, 10.2, 10.4, 10.1, 10.2, 10.2, 10.2, 10.1, 10.1, 10.3, 10.4, 10.0, 10.2, 10.6, 10.7, 11.3, 11.3, 11.3, 11.3, 11.2, 11.1, 11.4, 11.2, 11.1]
Escrito en InfluxDB: 9.2°C
Últimos valores de temperatura: [10.4, 10.4, 10.4, 10.4, 11.2, 11.3, 11.3, 11.3, 11.3, 11.3, 11.2, 11.0, 11.3, 11.3, 11.2, 11.2, 11.2, 9.2, 9.4, 9.3, 9.3, 9.2, 10.1, 10.3, 10.1, 10.2, 10.4, 10.1, 10.2, 10.2, 10.2, 10.1, 10.1, 10.3, 10.4, 10.0, 10.2, 10.6, 10.7, 11.3, 11.3, 11.3, 11.3, 11.2, 11.1, 11.4, 11.2]
Escrito en InfluxDB: 9.1°C
Últimos valores de temperatura: [10.4, 10.4, 10.4, 10.4, 11.2, 11.3, 11.3, 11.3, 11.3, 11.3, 11.2, 11.0, 11.3, 11.3, 11.2, 11.2, 11.2, 9.1, 9.2, 9.4, 9.3, 9.3, 9.2, 10.1, 10.3, 10.1, 10.2, 10.4, 10.1, 10.2, 10.2, 10.2, 10.1, 10.1, 10.3, 10.4, 10.0, 10.2, 10.6, 10.7, 11.3, 11.3, 11.3, 11.3, 11.2, 11.1, 11.4]
Escrito en InfluxDB: 10.4°C
Últimos valores de temperatura: [10.4, 10.4, 10.4, 10.4, 11.2, 11.3, 11.3, 11.3, 11.3, 11.3, 11.2, 11.0, 11.3, 11.3, 11.2, 11.2, 11.2, 10.4, 9.1, 9.2, 9.4, 9.3, 9.3, 9.2, 10.1, 10.3, 10.1, 10.2, 10.4, 10.1, 10.2, 10.2, 10.2, 10.1, 10.1, 10.3, 10.4, 10.0, 10.2, 10.6, 10.7, 11.3, 11.3, 11.3, 11.3, 11.2, 11.1]
Escrito en InfluxDB: 10.1°C
Últimos valores de temperatura: [10.4, 10.4, 10.4, 10.4, 11.2, 11.3, 11.3, 11.3, 11.3, 11.3, 11.2, 11.0, 11.3, 11.3, 11.2, 11.2, 11.2, 10.1, 10.4, 9.1, 9.2, 9.4, 9.3, 9.3, 9.2, 10.1, 10.3, 10.1, 10.2, 10.4, 10.1, 10.2, 10.2, 10.2, 10.1, 10.1, 10.3, 10.4, 10.0, 10.2, 10.6, 10.7, 11.3, 11.3, 11.3, 11.3, 11.2]
Escrito en InfluxDB: 10.1°C
Últimos valores de temperatura: [10.4, 10.4, 10.4, 10.4, 11.2, 11.3, 11.3, 11.3, 11.3, 11.3, 11.2, 11.0, 11.3, 11.3, 11.2, 11.2, 11.2, 10.1, 10.1, 10.4, 9.1, 9.2, 9.4, 9.3, 9.3, 9.2, 10.1, 10.3, 10.1, 10.2, 10.4, 10.1, 10.2, 10.2, 10.2, 10.1, 10.1, 10.3, 10.4, 10.0, 10.2, 10.6, 10.7, 11.3, 11.3, 11.3, 11.3]
Escrito en InfluxDB: 9.3°C
Últimos valores de temperatura: [10.4, 10.4, 10.4, 10.4, 11.2, 11.3, 11.3, 11.3, 11.3, 11.3, 11.2, 11.0, 11.3, 11.3, 11.2, 11.2, 11.2, 9.3, 10.1, 10.1, 10.4, 9.1, 9.2, 9.4, 9.3, 9.3, 9.2, 10.1, 10.3, 10.1, 10.2, 10.4, 10.1, 10.2, 10.2, 10.2, 10.1, 10.1, 10.3, 10.4, 10.0, 10.2, 10.6, 10.7, 11.3, 11.3, 11.3]
Escrito en InfluxDB: 9.1°C
Últimos valores de temperatura: [10.4, 10.4, 10.4, 10.4, 11.2, 11.3, 11.3, 11.3, 11.3, 11.3, 11.2, 11.0, 11.3, 11.3, 11.2, 11.2, 11.2, 9.1, 9.3, 10.1, 10.1, 10.4, 9.1, 9.2, 9.4, 9.3, 9.3, 9.2, 10.1, 10.3, 10.1, 10.2, 10.4, 10.1, 10.2, 10.2, 10.2, 10.1, 10.1, 10.3, 10.4, 10.0, 10.2, 10.6, 10.7, 11.3, 11.3]
Escrito en InfluxDB: 9.3°C
Últimos valores de temperatura: [10.4, 10.4, 10.4, 10.4, 11.2, 11.3, 11.3, 11.3, 11.3, 11.3, 11.2, 11.0, 11.3, 11.3, 11.2, 11.2, 11.2, 9.3, 9.1, 9.3, 10.1, 10.1, 10.4, 9.1, 9.2, 9.4, 9.3, 9.3, 9.2, 10.1, 10.3, 10.1, 10.2, 10.4, 10.1, 10.2, 10.2, 10.2, 10.1, 10.1, 10.3, 10.4, 10.0, 10.2, 10.6, 10.7, 11.3]
Escrito en InfluxDB: 10.1°C
Últimos valores de temperatura: [10.4, 10.4, 10.4, 10.4, 11.2, 11.3, 11.3, 11.3, 11.3, 11.3, 11.2, 11.0, 11.3, 11.3, 11.2, 11.2, 11.2, 10.1, 9.3, 9.1, 9.3, 10.1, 10.1, 10.4, 9.1, 9.2, 9.4, 9.3, 9.3, 9.2, 10.1, 10.3, 10.1, 10.2, 10.4, 10.1, 10.2, 10.2, 10.2, 10.1, 10.1, 10.3, 10.4, 10.0, 10.2, 10.6, 10.7]
Escrito en InfluxDB: 10.1°C
Últimos valores de temperatura: [10.4, 10.4, 10.4, 10.4, 11.2, 11.3, 11.3, 11.3, 11.3, 11.3, 11.2, 11.0, 11.3, 11.3, 11.2, 11.2, 11.2, 10.1, 10.1, 9.3, 9.1, 9.3, 10.1, 10.1, 10.4, 9.1, 9.2, 9.4, 9.3, 9.3, 9.2, 10.1, 10.3, 10.1, 10.2, 10.4, 10.1, 10.2, 10.2, 10.2, 10.1, 10.1, 10.3, 10.4, 10.0, 10.2, 10.6]
Escrito en InfluxDB: 11.3°C
Últimos valores de temperatura: [10.4, 10.4, 10.4, 10.4, 11.2, 11.3, 11.3, 11.3, 11.3, 11.3, 11.2, 11.0, 11.3, 11.3, 11.2, 11.2, 11.2, 11.3, 10.1, 10.1, 9.3, 9.1, 9.3, 10.1, 10.1, 10.4, 9.1, 9.2, 9.4, 9.3, 9.3, 9.2, 10.1, 10.3, 10.1, 10.2, 10.4, 10.1, 10.2, 10.2, 10.2, 10.1, 10.1, 10.3, 10.4, 10.0, 10.2]
Escrito en InfluxDB: 11.1°C
Últimos valores de temperatura: [10.4, 10.4, 10.4, 10.4, 11.2, 11.3, 11.3, 11.3, 11.3, 11.3, 11.2, 11.0, 11.3, 11.3, 11.2, 11.2, 11.2, 11.1, 11.3, 10.1, 10.1, 9.3, 9.1, 9.3, 10.1, 10.1, 10.4, 9.1, 9.2, 9.4, 9.3, 9.3, 9.2, 10.1, 10.3, 10.1, 10.2, 10.4, 10.1, 10.2, 10.2, 10.2, 10.1, 10.1, 10.3, 10.4, 10.0]
Escrito en InfluxDB: 11.1°C
Últimos valores de temperatura: [10.4, 10.4, 10.4, 10.4, 11.2, 11.3, 11.3, 11.3, 11.3, 11.3, 11.2, 11.0, 11.3, 11.3, 11.2, 11.2, 11.2, 11.1, 11.1, 11.3, 10.1, 10.1, 9.3, 9.1, 9.3, 10.1, 10.1, 10.4, 9.1, 9.2, 9.4, 9.3, 9.3, 9.2, 10.1, 10.3, 10.1, 10.2, 10.4, 10.1, 10.2, 10.2, 10.2, 10.1, 10.1, 10.3, 10.4]
Escrito en InfluxDB: 11.0°C
Últimos valores de temperatura: [10.4, 10.4, 10.4, 10.4, 11.2, 11.3, 11.3, 11.3, 11.3, 11.3, 11.2, 11.0, 11.3, 11.3, 11.2, 11.2, 11.2, 11.0, 11.1, 11.1, 11.3, 10.1, 10.1, 9.3, 9.1, 9.3, 10.1, 10.1, 10.4, 9.1, 9.2, 9.4, 9.3, 9.3, 9.2, 10.1, 10.3, 10.1, 10.2, 10.4, 10.1, 10.2, 10.2, 10.2, 10.1, 10.1, 10.3]
Escrito en InfluxDB: 12.0°C
Últimos valores de temperatura: [10.4, 10.4, 10.4, 10.4, 11.2, 11.3, 11.3, 11.3, 11.3, 11.3, 11.2, 11.0, 11.3, 11.3, 11.2, 11.2, 11.2, 12.0, 11.0, 11.1, 11.1, 11.3, 10.1, 10.1, 9.3, 9.1, 9.3, 10.1, 10.1, 10.4, 9.1, 9.2, 9.4, 9.3, 9.3, 9.2, 10.1, 10.3, 10.1, 10.2, 10.4, 10.1, 10.2, 10.2, 10.2, 10.1, 10.1]
Escrito en InfluxDB: 12.4°C
Últimos valores de temperatura: [10.4, 10.4, 10.4, 10.4, 11.2, 11.3, 11.3, 11.3, 11.3, 11.3, 11.2, 11.0, 11.3, 11.3, 11.2, 11.2, 11.2, 12.4, 12.0, 11.0, 11.1, 11.1, 11.3, 10.1, 10.1, 9.3, 9.1, 9.3, 10.1, 10.1, 10.4, 9.1, 9.2, 9.4, 9.3, 9.3, 9.2, 10.1, 10.3, 10.1, 10.2, 10.4, 10.1, 10.2, 10.2, 10.2, 10.1]
Traceback (most recent call last):
  File "/usr/local/lib/python3.9/site-packages/urllib3/connection.py", line 198, in _new_conn
    sock = connection.create_connection(
  File "/usr/local/lib/python3.9/site-packages/urllib3/util/connection.py", line 85, in create_connection
    raise err
  File "/usr/local/lib/python3.9/site-packages/urllib3/util/connection.py", line 73, in create_connection
    sock.connect(sa)
OSError: [Errno 101] Network is unreachable

The above exception was the direct cause of the following exception:

Traceback (most recent call last):
  File "/usr/local/lib/python3.9/site-packages/urllib3/connectionpool.py", line 787, in urlopen
    response = self._make_request(
  File "/usr/local/lib/python3.9/site-packages/urllib3/connectionpool.py", line 493, in _make_request
    conn.request(
  File "/usr/local/lib/python3.9/site-packages/urllib3/connection.py", line 445, in request
    self.endheaders()
  File "/usr/local/lib/python3.9/http/client.py", line 1280, in endheaders
    self._send_output(message_body, encode_chunked=encode_chunked)
  File "/usr/local/lib/python3.9/http/client.py", line 1040, in _send_output
    self.send(msg)
  File "/usr/local/lib/python3.9/http/client.py", line 980, in send
    self.connect()
  File "/usr/local/lib/python3.9/site-packages/urllib3/connection.py", line 276, in connect
    self.sock = self._new_conn()
  File "/usr/local/lib/python3.9/site-packages/urllib3/connection.py", line 213, in _new_conn
    raise NewConnectionError(
urllib3.exceptions.NewConnectionError: <urllib3.connection.HTTPConnection object at 0x790136269400>: Failed to establish a new connection: [Errno 101] Network is unreachable

The above exception was the direct cause of the following exception:

Traceback (most recent call last):
  File "/usr/local/lib/python3.9/site-packages/requests/adapters.py", line 667, in send
    resp = conn.urlopen(
  File "/usr/local/lib/python3.9/site-packages/urllib3/connectionpool.py", line 841, in urlopen
    retries = retries.increment(
  File "/usr/local/lib/python3.9/site-packages/urllib3/util/retry.py", line 519, in increment
    raise MaxRetryError(_pool, url, reason) from reason  # type: ignore[arg-type]
urllib3.exceptions.MaxRetryError: HTTPConnectionPool(host='api.weatherapi.com', port=80): Max retries exceeded with url: /v1/current.json?key=d0a78c77a34b4d55879212336251302&q=Sant%20Quirze%20del%20Vall%C3%A9s&aqi=no (Caused by NewConnectionError('<urllib3.connection.HTTPConnection object at 0x790136269400>: Failed to establish a new connection: [Errno 101] Network is unreachable'))

During handling of the above exception, another exception occurred:

Traceback (most recent call last):
  File "/app/weatherapi.py", line 37, in <module>
    temperature = get_weather()
  File "/app/weatherapi.py", line 26, in get_weather
    response = requests.get(url)
  File "/usr/local/lib/python3.9/site-packages/requests/api.py", line 73, in get
    return request("get", url, params=params, **kwargs)
  File "/usr/local/lib/python3.9/site-packages/requests/api.py", line 59, in request
    return session.request(method=method, url=url, **kwargs)
  File "/usr/local/lib/python3.9/site-packages/requests/sessions.py", line 589, in request
    resp = self.send(prep, **send_kwargs)
  File "/usr/local/lib/python3.9/site-packages/requests/sessions.py", line 703, in send
    r = adapter.send(request, **kwargs)
  File "/usr/local/lib/python3.9/site-packages/requests/adapters.py", line 700, in send
    raise ConnectionError(e, request=request)
requests.exceptions.ConnectionError: HTTPConnectionPool(host='api.weatherapi.com', port=80): Max retries exceeded with url: /v1/current.json?key=d0a78c77a34b4d55879212336251302&q=Sant%20Quirze%20del%20Vall%C3%A9s&aqi=no (Caused by NewConnectionError('<urllib3.connection.HTTPConnection object at 0x790136269400>: Failed to establish a new connection: [Errno 101] Network is unreachable'))
Escrito en InfluxDB: 13.3°C
Últimos valores de temperatura: [10.4, 10.4, 10.4, 10.4, 11.2, 11.3, 11.3, 11.3, 11.3, 11.3, 11.2, 11.0, 11.3, 11.3, 11.2, 11.2, 11.2, 13.3, 12.4, 12.0, 11.0, 11.1, 11.1, 11.3, 10.1, 10.1, 9.3, 9.1, 9.3, 10.1, 10.1, 10.4, 9.1, 9.2, 9.4, 9.3, 9.3, 9.2, 10.1, 10.3, 10.1, 10.2, 10.4, 10.1, 10.2, 10.2, 10.2]
Escrito en InfluxDB: 14.1°C
Últimos valores de temperatura: [10.4, 10.4, 10.4, 10.4, 11.2, 11.3, 11.3, 11.3, 11.3, 11.3, 11.2, 11.0, 11.3, 11.3, 11.2, 11.2, 11.2, 14.1, 13.3, 12.4, 12.0, 11.0, 11.1, 11.1, 11.3, 10.1, 10.1, 9.3, 9.1, 9.3, 10.1, 10.1, 10.4, 9.1, 9.2, 9.4, 9.3, 9.3, 9.2, 10.1, 10.3, 10.1, 10.2, 10.4, 10.1, 10.2, 10.2]
Escrito en InfluxDB: 14.1°C
Últimos valores de temperatura: [10.4, 10.4, 10.4, 10.4, 11.2, 11.3, 11.3, 11.3, 11.3, 11.3, 11.2, 11.0, 11.3, 11.3, 11.2, 11.2, 11.2, 14.1, 14.1, 13.3, 12.4, 12.0, 11.0, 11.1, 11.1, 11.3, 10.1, 10.1, 9.3, 9.1, 9.3, 10.1, 10.1, 10.4, 9.1, 9.2, 9.4, 9.3, 9.3, 9.2, 10.1, 10.3, 10.1, 10.2, 10.4, 10.1, 10.2]
Escrito en InfluxDB: 15.0°C
Últimos valores de temperatura: [10.4, 10.4, 10.4, 10.4, 11.2, 11.3, 11.3, 11.3, 11.3, 11.3, 11.2, 11.0, 11.3, 11.3, 11.2, 11.2, 11.2, 15.0, 14.1, 14.1, 13.3, 12.4, 12.0, 11.0, 11.1, 11.1, 11.3, 10.1, 10.1, 9.3, 9.1, 9.3, 10.1, 10.1, 10.4, 9.1, 9.2, 9.4, 9.3, 9.3, 9.2, 10.1, 10.3, 10.1, 10.2, 10.4, 10.1]
Escrito en InfluxDB: 15.2°C
Últimos valores de temperatura: [10.4, 10.4, 10.4, 10.4, 11.2, 11.3, 11.3, 11.3, 11.3, 11.3, 11.2, 11.0, 11.3, 11.3, 11.2, 11.2, 11.2, 15.2, 15.0, 14.1, 14.1, 13.3, 12.4, 12.0, 11.0, 11.1, 11.1, 11.3, 10.1, 10.1, 9.3, 9.1, 9.3, 10.1, 10.1, 10.4, 9.1, 9.2, 9.4, 9.3, 9.3, 9.2, 10.1, 10.3, 10.1, 10.2, 10.4]
Escrito en InfluxDB: 14.2°C
Últimos valores de temperatura: [10.4, 10.4, 10.4, 10.4, 11.2, 11.3, 11.3, 11.3, 11.3, 11.3, 11.2, 11.0, 11.3, 11.3, 11.2, 11.2, 11.2, 14.2, 15.2, 15.0, 14.1, 14.1, 13.3, 12.4, 12.0, 11.0, 11.1, 11.1, 11.3, 10.1, 10.1, 9.3, 9.1, 9.3, 10.1, 10.1, 10.4, 9.1, 9.2, 9.4, 9.3, 9.3, 9.2, 10.1, 10.3, 10.1, 10.2]
Escrito en InfluxDB: 14.4°C
Últimos valores de temperatura: [10.4, 10.4, 10.4, 10.4, 11.2, 11.3, 11.3, 11.3, 11.3, 11.3, 11.2, 11.0, 11.3, 11.3, 11.2, 11.2, 11.2, 14.4, 14.2, 15.2, 15.0, 14.1, 14.1, 13.3, 12.4, 12.0, 11.0, 11.1, 11.1, 11.3, 10.1, 10.1, 9.3, 9.1, 9.3, 10.1, 10.1, 10.4, 9.1, 9.2, 9.4, 9.3, 9.3, 9.2, 10.1, 10.3, 10.1]
Escrito en InfluxDB: 14.2°C
Últimos valores de temperatura: [10.4, 10.4, 10.4, 10.4, 11.2, 11.3, 11.3, 11.3, 11.3, 11.3, 11.2, 11.0, 11.3, 11.3, 11.2, 11.2, 11.2, 14.2, 14.4, 14.2, 15.2, 15.0, 14.1, 14.1, 13.3, 12.4, 12.0, 11.0, 11.1, 11.1, 11.3, 10.1, 10.1, 9.3, 9.1, 9.3, 10.1, 10.1, 10.4, 9.1, 9.2, 9.4, 9.3, 9.3, 9.2, 10.1, 10.3]
Escrito en InfluxDB: 14.2°C
Últimos valores de temperatura: [10.4, 10.4, 10.4, 10.4, 11.2, 11.3, 11.3, 11.3, 11.3, 11.3, 11.2, 11.0, 11.3, 11.3, 11.2, 11.2, 11.2, 14.2, 14.2, 14.4, 14.2, 15.2, 15.0, 14.1, 14.1, 13.3, 12.4, 12.0, 11.0, 11.1, 11.1, 11.3, 10.1, 10.1, 9.3, 9.1, 9.3, 10.1, 10.1, 10.4, 9.1, 9.2, 9.4, 9.3, 9.3, 9.2, 10.1]
Escrito en InfluxDB: 15.3°C
Últimos valores de temperatura: [10.4, 10.4, 10.4, 10.4, 11.2, 11.3, 11.3, 11.3, 11.3, 11.3, 11.2, 11.0, 11.3, 11.3, 11.2, 11.2, 11.2, 15.3, 14.2, 14.2, 14.4, 14.2, 15.2, 15.0, 14.1, 14.1, 13.3, 12.4, 12.0, 11.0, 11.1, 11.1, 11.3, 10.1, 10.1, 9.3, 9.1, 9.3, 10.1, 10.1, 10.4, 9.1, 9.2, 9.4, 9.3, 9.3, 9.2]
Escrito en InfluxDB: 15.0°C
Últimos valores de temperatura: [10.4, 10.4, 10.4, 10.4, 11.2, 11.3, 11.3, 11.3, 11.3, 11.3, 11.2, 11.0, 11.3, 11.3, 11.2, 11.2, 11.2, 15.0, 15.3, 14.2, 14.2, 14.4, 14.2, 15.2, 15.0, 14.1, 14.1, 13.3, 12.4, 12.0, 11.0, 11.1, 11.1, 11.3, 10.1, 10.1, 9.3, 9.1, 9.3, 10.1, 10.1, 10.4, 9.1, 9.2, 9.4, 9.3, 9.3]
